<?xml version="1.0"?>
<robot name="RP_Arm">
    <!-- This first link called "world" is empty -->
    <link name="world"></link>

    <!-- A simple fixed joint from our empty world link, to our base. -->
    <!-- The base origin is offset from the world origin. -->
    <joint name="base_joint" type="fixed">
        <origin xyz="1.5 0 0" rpy="0 0 0"/>
        <parent link="world"/>
        <child link="base_link"/>        
    </joint>

    <!-- base_link is a large rectangular plate. Some things to note: -->
    <!-- - We set the visual origin Z to half the box height, so that the link origin sits at the bottom of the box -->
    <!-- - We set the collision to be identical to the visual -->
    <!-- - We specified the colour manually (but still need to enter a name) -->
    <!-- - We specified all the inertial parameters manually -->
    <link name="base_link">
        <visual>
            <origin xyz="0 0 0.05" rpy="0 0 0"/>
            <geometry>
                <box size="2.5 1.5 0.1" />
            </geometry>
            <material name="green">
                <color rgba="0.2 1 0.2 1"/>
            </material>
        </visual>
        <collision>
            <origin xyz="0 0 0.05" rpy="0 0 0"/>
            <geometry>
                <box size="2.5 1.5 0.1" />
            </geometry>
        </collision>
        <inertial>
            <origin xyz="0 0 0.05" rpy="0 0 0"/>
            <mass value="12" />
            <inertia ixx="2.26" ixy="0.0" ixz="0.0" iyy="6.26" iyz="0.0" izz="8.5" />
        </inertial>
    </link>

    <joint name="base_arm_joint" type="revolute"> 
        <origin xyz="0 0 0.7 " rpy="0 0 0"/>
        <parent link="base_link"/>
        <child link="arm_link"/>
        <axis xyz="0 0 -1"/>
        <limit lower="0" upper="6.28" velocity="100" effort="100"/> 
    </joint> 

    <link name="arm_link">
        <visual>
            <origin xyz="0 0 0" rpy="0 0 0"/>
            <geometry>
                <cylinder radius="0.1" length="1.2" />
            </geometry>
            <material name="white">
                <color rgba="1 1 1 1"/>
            </material>
        </visual>
        <collision>
            <origin xyz="0 0 0" rpy="0 0 0"/>
            <geometry>
                <cylinder radius="0.1" length="1.2" />
            </geometry>
        </collision>
    </link>

    <joint name="arm_slider_rod_joint" type="fixed">
        <origin xyz="0.6 0 0.7" rpy="0 0 0"/>
        <parent link="arm_link"/>
        <child link="rod_link"/>        
    </joint>

    <link name="rod_link">
        <visual>
            <origin xyz="0 0 0" rpy="0 0 0"/>
            <geometry>
                <box size="1.4 0.05 0.2" />
            </geometry>
            <material name="black">
                <color rgba="0 0 0 1"/>
            </material>
        </visual>
        <collision>
            <origin xyz="0 0 0" rpy="0 0 0"/>
            <geometry>
                <box size="1.4 0.05 0.2" />
            </geometry>
        </collision>

    </link>

    <joint name="slider_joint" type="prismatic">
        <origin xyz="0 0 0" rpy="0 0 0"/>
        <parent link="rod_link"/>
        <child link="slider_link"/>
        <axis xyz="1 0 0"/>
        <limit lower="0.6" upper="-0.6" velocity="100" effort="100"/> 
    </joint>
   
   <link name="slider_link">
        <visual>
            <origin xyz="0 0 0" rpy="0 0 0"/>
            <geometry>
                <box size="0.2 0.07 0.2" />
            </geometry>
        </visual>
        <collision>
            <origin xyz="0 0 0" rpy="0 0 0"/>
            <geometry>
                <box size="0.2 0.07 0.2" />
            </geometry>
        </collision>
    </link>

    <joint name="slider_EE_joint" type="fixed">
        <origin xyz="0 -0.08 0" rpy="1.55 0 0"/>
        <parent link="slider_link"/>
        <child link="end_effector"/>   
    </joint>

    <link name="end_effector">
        <visual>
            <origin xyz="0 0 0" rpy="0 0 0"/>
            <geometry>
                <cylinder radius="0.02" length="0.16" />
            </geometry>
            <material name="blue">
                <color rgba="0.2 0.2 1 1"/>
            </material>
        </visual>
        <collision>
            <origin xyz="0 0 0" rpy="0 0 0"/>
            <geometry>
                <cylinder radius="0.02" length="0.16" />
            </geometry>
        </collision>
    </link>
</robot>